Workbook

Sheet Pitch Checklist
B1: Pitch Checklist
B2: Scoring: ✅ Best Practice = 2 | ⚠️ Minimally Meets = 1 | ❌ Does Not Meet = 0 | Not Applicable = excluded. Set the rating on each criterion in the 'Pitch Scorecard' tab; scores roll up here automatically. Green rows = newly recommended categories.
B3: Category | C3: Checklist Description | D3: Criteria | E3: ❌ Does Not Meet | F3: ⚠️ Minimally Meets | G3: ✅ Best Practice | H3: Evaluation Rating | I3: Score (0–2) | J3: Comments / Feedback
B4: STRUCTURE | C4: The deck includes all essential sections to ensure a compelling, well-structured proposal: − Executive Summary − Our Understanding (Client’s Challenges and Needs) − Bristlecone’s Point of View (PoV) − Proposed Solution (Approach, Methodology, Key Components) − Business Case / Value Delivered (Expected Impact, ROI) − Examples & Case Studies (Relevant Success Stories) − Accelerators & Differentiators (Proprietary Tools, Frameworks) − Value Proposition (Pricing, Investment Details) − Why Bristlecone? (Key Reasons We’re the Best Partner) − Additional Value-Added Services (Recommendations Beyond the Ask that may be Differentiators) | D4: CLIENT-SPECIFIC RELEVANCE | E4: Generic content that could apply to any client. | F4: Some customization, but still largely templated. | G4: Fully tailored to the client, incorporating industry, domain, and solution-specific details. | H4: ✅ Best Practice | I4: =IF(H4="✅ Best Practice",2,IF(H4="⚠️ Minimally Meets",1,IF(H4="❌ Does Not Meet",0,"—"))) -> 2 | J4: Deeply tailored: 77 company codes, 190 plants, and named third-party systems (Salesforce, Workday, Wells Fargo, HSBC, CIBC, UBS) — not boilerplate.
D5: THOUGHT LEADERSHIP | E5: No additional recommendations beyond the RFP scope. | F5: Some extra insights, but not well-developed. | G5: Provides a strong Bristlecone PoV, proactively recommending relevant services based on expertise. | H5: ✅ Best Practice | I5: =IF(H5="✅ Best Practice",2,IF(H5="⚠️ Minimally Meets",1,IF(H5="❌ Does Not Meet",0,"—"))) -> 2 | J5: BW-on-HANA, HANA Cloud, and Reporting 'approach options' slides (pp.99-101) show a genuine Bristlecone PoV with pros/cons and explicit recommendations, beyond bare scope.
D6: EXECUTIVE SUMMARY EFFECTIVENESS | E6: No executive summary, or it does not stand alone. | F6: Summary present but descriptive rather than persuasive; buries the value. | G6: Compelling, stand-alone exec summary leading with client value, outcomes, and why Bristlecone. | H6: ⚠️ Minimally Meets | I6: =IF(H6="✅ Best Practice",2,IF(H6="⚠️ Minimally Meets",1,IF(H6="❌ Does Not Meet",0,"—"))) -> 1 | J6: Exec summary (slide 4) maps objectives -> approach -> outcomes but reads as a graphic/bullet mapping rather than a persuasive stand-alone narrative; no closing 'why Bristlecone' to anchor it.
D7: NARRATIVE FLOW & COHERENCE | E7: Sections feel disconnected; no logical storyline. | F7: Logical order but transitions/threading of win themes are weak. | G7: Sections build a coherent, client-centered storyline from problem to value. | H7: ⚠️ Minimally Meets | I7: =IF(H7="✅ Best Practice",2,IF(H7="⚠️ Minimally Meets",1,IF(H7="❌ Does Not Meet",0,"—"))) -> 1 | J7: Logical phase ordering overall, but the Organizational Change Management section (slide 66-67) is a blank stub, and the deck never resolves into a differentiation/close section.
B8: CUSTOMER CENTRICITY | C8: The proposal demonstrates a deep understanding of the client’s strategy, current situation, and specific requirements by: − Clearly connecting the proposed solution to the client’s strategic priorities and business objectives. − Framing the narrative from the client’s perspective, not just Bristlecone’s. − Grounding recommendations in industry and domain-specific context to enhance credibility. | D8: CLIENT-SPECIFIC INSIGHTS | E8: Generic content with little to no client or industry specificity. | F8: Largely standardized deck with minimal tailoring (e.g., just rewording the client’s RFP). | G8: Goes beyond restating client needs – demonstrates strategic understanding of their business, industry, and challenges. | H8: ✅ Best Practice | I8: =IF(H8="✅ Best Practice",2,IF(H8="⚠️ Minimally Meets",1,IF(H8="❌ Does Not Meet",0,"—"))) -> 2 | J8: Extensive Semtech-specific detail throughout (systems, scope counts, integrations).
D9: SOLUTION ALIGNMENT | E9: Weak or no connection between the solution and the client’s strategic priorities. | F9: Some linkage, but lacks depth in explaining how Bristlecone’s approach uniquely addresses the client’s needs. | G9: Solution is clearly mapped to the client’s goals, with strong rationale and supporting details. | H9: ✅ Best Practice | I9: =IF(H9="✅ Best Practice",2,IF(H9="⚠️ Minimally Meets",1,IF(H9="❌ Does Not Meet",0,"—"))) -> 2 | J9: Slide 4 explicitly maps Semtech's strategic objectives to Bristlecone's approach and expected outcomes.
D10: COMPELLING STORYTELLING | E10: Proposal is written from Bristlecone’s perspective, not the client’s. | F10: Some elements of client perspective but not consistently applied. | G10: The story is structured around the client’s challenges and goals, making them the hero of the narrative. | H10: ⚠️ Minimally Meets | I10: =IF(H10="✅ Best Practice",2,IF(H10="⚠️ Minimally Meets",1,IF(H10="❌ Does Not Meet",0,"—"))) -> 1 | J10: Large stretches (Finance/Manufacturing/Sales 'representative benefits' slides, source: SAP) are generic SAP marketing content, not written from Semtech's specific vantage point.
B11: THOUGHT LEADERSHIP & EXPERTISE | C11: The proposal effectively showcases Bristlecone’s expertise and credibility across all relevant capabilities required for the scope of work, including: Industry Knowledge: Deep understanding of sector-specific challenges and opportunities. Technology Knowledge: Expertise in relevant package applications and partner technologies. AI Knowledge: Demonstrated understanding of AI-driven solutions and their applications (if applicable). Domain Knowledge: Specialization in key areas such as Planning, Procurement, Operations, and Manufacturing. Program Management: Proven methodologies for project implementation and execution. Change Management: Ability to drive adoption, transformation, and impact. Additionally, the proposal should include a Bristlecone Point of View (PoV) on: − Industry Trends and Challenges − AI Opportunities and Innovation − The Evolving SCM Landscape Where applicable, thought leadership should be reinforced with data, case studies, and public citations to build credibility. | D11: EXPERTISE COVERAGE | E11: Key capabilities missing or weakly represented. | F11: Lists expertise areas but lacks depth or compelling examples. | G11: Fully covers all expertise areas with detailed supporting content. | H11: ✅ Best Practice | I11: =IF(H11="✅ Best Practice",2,IF(H11="⚠️ Minimally Meets",1,IF(H11="❌ Does Not Meet",0,"—"))) -> 2 | J11: Comprehensive coverage across S/4HANA, BTP/BAIP, BDC, aATP, and IBP domains.
D12: PROOF & THOUGHT LEADERSHIP | E12: Relies on generic statements without proof points. | F12: Some examples included, but lacks depth, maturity, or industry citations. | G12: Uses strong case studies, public citations, and thought leadership insights to reinforce credibility. | H12: ⚠️ Minimally Meets | I12: =IF(H12="✅ Best Practice",2,IF(H12="⚠️ Minimally Meets",1,IF(H12="❌ Does Not Meet",0,"—"))) -> 1 | J12: Proof points in the benefit tables are attributed to SAP's own customer references (e.g. PASHA Holding, Lexmark), not Bristlecone-specific evidence or citations.
D13: POINT OF VIEW (POV) | E13: No Bristlecone PoV or generic industry statements. | F13: PoV included but lacks specificity or unique perspective. | G13: Strong, well-defined Bristlecone PoV with insights, recommendations, and supporting data. | H13: ✅ Best Practice | I13: =IF(H13="✅ Best Practice",2,IF(H13="⚠️ Minimally Meets",1,IF(H13="❌ Does Not Meet",0,"—"))) -> 2 | J13: Approach-options slides (BW, HANA Cloud, Reporting) present a well-defined, specific PoV with clear recommendations and rationale.
D14: DEMONSTRATIONS & EVIDENCE | E14: No demos or tangible proof where relevant. | F14: Some evidence included, but not fully developed. | G14: Where applicable, includes live demos, interactive elements, or detailed use cases. | H14: ⚠️ Minimally Meets | I14: =IF(H14="✅ Best Practice",2,IF(H14="⚠️ Minimally Meets",1,IF(H14="❌ Does Not Meet",0,"—"))) -> 1 | J14: Tools like PO-to-SO Automation and BTP Genie are described conceptually; no demo, screenshot, or interactive proof shown.
B15: PARTNERSHIPS | C15: For deals involving technology or service partnerships, the proposal should clearly articulate: − The breadth and depth of the partnership. − The value of the partnership to the success of the program. − Examples of past successful partnerships, aligned to the deal. − If the partnership is new or early-stage, the proposal must define a clear path to successful delivery. − Joint case studies should be included, where appropriate, to demonstrate proven collaboration and execution. If no external partnerships are relevant to the proposal, this section is marked N/A. | D15: PARTNERSHIP VALUE DEFINITION | E15: Standard, generic content with no tie to the deal. | F15: Includes partnership details, but lacks strong alignment to this specific opportunity. | G15: Clearly defines how the partnership enhances program success with tailored insights. | H15: ❌ Does Not Meet | I15: =IF(H15="✅ Best Practice",2,IF(H15="⚠️ Minimally Meets",1,IF(H15="❌ Does Not Meet",0,"—"))) -> 0 | J15: Entire program is built on SAP (S/4HANA, BTP, BDC) but there is no partnership narrative — no joint delivery role or SAP-attributed success story. Naming the platform is not a partnership story per the checklist's own guidance, so this is scored low rather than marked N/A.
D16: PROOF OF SUCCESS | E16: No examples or only vague references to past success. | F16: Some success stories included, but lacks depth or relevance. | G16: Robust, well-aligned case studies showcasing joint success with partners. | H16: ❌ Does Not Meet | I16: =IF(H16="✅ Best Practice",2,IF(H16="⚠️ Minimally Meets",1,IF(H16="❌ Does Not Meet",0,"—"))) -> 0 | J16: No joint case studies or proof of success co-delivered with SAP or any other partner.
D17: PATH TO SUCCESS FOR NEW RELATIONSHIPS | E17: No roadmap for execution with an early-stage partner. | F17: Some consideration given, but lacks details on collaboration and risk mitigation. | G17: Well-defined success path, including roles, responsibilities, and joint execution strategies. | H17: ❌ Does Not Meet | I17: =IF(H17="✅ Best Practice",2,IF(H17="⚠️ Minimally Meets",1,IF(H17="❌ Does Not Meet",0,"—"))) -> 0 | J17: No roadmap for how Bristlecone and SAP (or any partner) will collaborate on this specific engagement.
D18: COLLABORATION FACTORS | E18: No discussion of how Bristlecone, the partner, and the client will collaborate. | F18: Some reference to collaboration, but not fully developed. | G18: Clearly defines critical success factors for seamless partnership execution in this specific deal. | H18: ❌ Does Not Meet | I18: =IF(H18="✅ Best Practice",2,IF(H18="⚠️ Minimally Meets",1,IF(H18="❌ Does Not Meet",0,"—"))) -> 0 | J18: No discussion of Bristlecone/partner/client collaboration mechanics.
B19: TEAM | C19: The proposal should clearly define the Day 1 / Delivery Team, ensuring: − Key roles and responsibilities are identified. − Bios are included for all key personnel, tailored to highlight their fit for the proposed role and relevance to the client’s needs. − Client participation is well-defined, outlining expected roles and effort required at each key phase of the program. − A RACI matrix (Responsible, Accountable, Consulted, Informed) is included for key deliverables, ensuring clarity in ownership and execution. − FTE requirements by phase are specified at an actionable level (weekly/monthly) where applicable. | D19: KEY PERSONNEL & ROLES | E19: Key roles are missing or loosely defined. | F19: Full list of key roles included but lacks strong contextualization. | G19: Key roles fully defined with clear alignment to the deal. | H19: ⚠️ Minimally Meets | I19: =IF(H19="✅ Best Practice",2,IF(H19="⚠️ Minimally Meets",1,IF(H19="❌ Does Not Meet",0,"—"))) -> 1 | J19: Comprehensive role/track lists per workstream (slides 82-85), but no individuals are named — roles only, no contextualization to Semtech's specific challenges.
D20: BIOS & FIT FOR ROLE | E20: Generic bios with no relevance to this engagement. | F20: Bios included but not tailored to emphasize fit. | G20: Bios are client-specific, highlighting direct relevance to the project. | H20: ❌ Does Not Meet | I20: =IF(H20="✅ Best Practice",2,IF(H20="⚠️ Minimally Meets",1,IF(H20="❌ Does Not Meet",0,"—"))) -> 0 | J20: No bios anywhere in the deck — staffing tables show Role/Track + Geography only.
D21: CLIENT PARTICIPATION DEFINITION | E21: No mention of client engagement expectations. | F21: Some client requirements outlined, but not detailed. | G21: Client roles, responsibilities, and effort levels are well-defined across all phases. | H21: ⚠️ Minimally Meets | I21: =IF(H21="✅ Best Practice",2,IF(H21="⚠️ Minimally Meets",1,IF(H21="❌ Does Not Meet",0,"—"))) -> 1 | J21: Semtech's responsibilities are scattered across the Key Assumptions slides (UAT scripting, data harmonization, etc.) but never consolidated into a clear client-role section.
D22: RACI & EXECUTION READINESS | E22: RACI missing or incomplete. FTE commitments not defined. | F22: RACI included but lacks detail, and FTE estimates are not at an executable level. | G22: Fully developed RACI, with clear ownership and detailed FTE commitments by phase. | H22: ❌ Does Not Meet | I22: =IF(H22="✅ Best Practice",2,IF(H22="⚠️ Minimally Meets",1,IF(H22="❌ Does Not Meet",0,"—"))) -> 0 | J22: No RACI matrix anywhere; staffing tables list roles per workstream with no FTE quantification by phase.
D23: TEAM CONTINUITY / KEY-PERSON COMMITMENT | E23: No assurance the named team will deliver. | F23: Named team shown but no commitment to continuity (bait-and-switch risk). | G23: Explicit commitment that the proposed A-team will deliver, with continuity safeguards. | H23: ❌ Does Not Meet | I23: =IF(H23="✅ Best Practice",2,IF(H23="⚠️ Minimally Meets",1,IF(H23="❌ Does Not Meet",0,"—"))) -> 0 | J23: No language committing the proposed team to stay through delivery (bait-and-switch risk unaddressed).
B24: BRANDING | C24: The proposal maintains high professional and brand standards, ensuring: − Proper use of Bristlecone (or client-required) templates and layouts, including accurate logos. − Clean, visually appealing design aligned with Bristlecone’s branding guidelines. − Effective use of slide layouts to enhance storytelling rather than just presenting information. − High-quality, impactful visuals that support and strengthen the message. − Storytelling reinforces Bristlecone’s position as an SCM and AI expert, with clear differentiation. − External validation included, such as analyst reports, awards, recognitions, published thought leadership, and earned media, to reinforce Bristlecone’s credibility. − Spelling and grammar have been reviewed, ensuring a polished and professional final product (Hint: Use ChatGPT for proofreading). Material should also be optimized for the intended format: − Written Submission → More detailed, text-heavy content. − Oral Presentation → More visuals, lighter on text, engaging delivery. | D24: TEMPLATE & BRAND COMPLIANCE | E24: Template is misaligned with Bristlecone or client standards. | F24: Template is used correctly, but branding inconsistencies exist. | G24: Fully compliant with Bristlecone standards, visually polished, and professional. | H24: ✅ Best Practice | I24: =IF(H24="✅ Best Practice",2,IF(H24="⚠️ Minimally Meets",1,IF(H24="❌ Does Not Meet",0,"—"))) -> 2 | J24: Consistent, professional Bristlecone/Semtech co-branded template throughout (confirmed via rendered slides).
D25: STORYTELLING & POSITIONING | E25: Bristlecone’s expertise is unclear or weakly presented. | F25: Expertise is communicated but relies on ‘telling’ rather than strong proof points. | G25: Clear, compelling storytelling that reinforces Bristlecone’s AI-first, consulting-led SCM leadership. | H25: ⚠️ Minimally Meets | I25: =IF(H25="✅ Best Practice",2,IF(H25="⚠️ Minimally Meets",1,IF(H25="❌ Does Not Meet",0,"—"))) -> 1 | J25: Visually polished but leans on capability 'telling' (technical depth) over differentiated proof-point storytelling of Bristlecone's unique position.
D26: USE OF VISUALS | E26: Poor-quality or irrelevant images that do not enhance storytelling. | F26: Some visuals included but not fully optimized for impact. | G26: Powerful, high-quality images and visuals that enhance and support messaging. | H26: ✅ Best Practice | I26: =IF(H26="✅ Best Practice",2,IF(H26="⚠️ Minimally Meets",1,IF(H26="❌ Does Not Meet",0,"—"))) -> 2 | J26: Clean, well-produced graphics — timelines, org charts, architecture diagrams (confirmed via rendered slides).
D27: EXTERNAL VALIDATION & PROOF | E27: No citations, analyst reports, awards, or third-party credibility sources. | F27: Some external content included, but lacks strong validation. | G27: Strong supporting materials (analyst reports, awards, recognitions, thought leadership) reinforcing credibility. | H27: ⚠️ Minimally Meets | I27: =IF(H27="✅ Best Practice",2,IF(H27="⚠️ Minimally Meets",1,IF(H27="❌ Does Not Meet",0,"—"))) -> 1 | J27: Real client logos shown (slides 91-92, incl. a directly relevant Semiconductor reference), but no analyst reports, awards, or third-party citations.
D28: SPELLING, GRAMMAR & READABILITY | E28: Multiple errors in spelling, grammar, or formatting. | F28: Mostly clean but may have minor errors or inconsistencies. | G28: Fully proofed, polished, and easy to read with no distracting errors. | H28: ✅ Best Practice | I28: =IF(H28="✅ Best Practice",2,IF(H28="⚠️ Minimally Meets",1,IF(H28="❌ Does Not Meet",0,"—"))) -> 2 | J28: Clean and professional text throughout; no material spelling/grammar errors spotted.
D29: FORMAT OPTIMIZATION | E29: Not adjusted for intended delivery format (text-heavy presentation or too visual for a written submission). | F29: Some consideration given, but not fully optimized for audience engagement. | G29: Well-structured for intended use – concise and visual for presentations, detailed for written submission. | H29: ⚠️ Minimally Meets | I29: =IF(H29="✅ Best Practice",2,IF(H29="⚠️ Minimally Meets",1,IF(H29="❌ Does Not Meet",0,"—"))) -> 1 | J29: Several slides (21, 95-98) are extremely text/table-dense — more suited to a supporting document than a reviewable written submission or an oral walk-through.
B30: EXECUTIVE COMMITMENT | C30: The proposal effectively conveys Bristlecone’s commitment to the success of the program by: − Clearly articulating executive sponsorship and involvement from leadership. − Defining resource commitments in quantifiable terms (e.g., dedicated FTEs, SMEs, workshops, governance structure). − Ensuring pricing strategy discussions have factored in executive participation, SME availability, and overall engagement level. − Highlighting any outcome-based opportunities, including estimated impact and shared success models. − Scaling commitment appropriately based on the deal size and strategic importance to both Bristlecone and the client. | D30: CLARITY OF EXECUTIVE INVOLVEMENT | E30: Executive commitment is missing or vaguely referenced. | F30: Commitment is mentioned but lacks depth or quantification. | G30: Clearly defined executive participation, including named sponsors and their roles with specific and measurable commitment. | H30: ⚠️ Minimally Meets | I30: =IF(H30="✅ Best Practice",2,IF(H30="⚠️ Minimally Meets",1,IF(H30="❌ Does Not Meet",0,"—"))) -> 1 | J30: A 'Program Sponsor (BU Head)' role appears in the governance org chart (slide 63) but with no named individual or depth on their commitment.
D31: RESOURCE & SME COMMITMENT | E31: No mention of resource commitments. | F31: Some resource commitment is included, but not quantified. | G31: Quantifiable commitment (e.g., specific FTEs, SMEs, workshops) with clear alignment to program success. | H31: ⚠️ Minimally Meets | I31: =IF(H31="✅ Best Practice",2,IF(H31="⚠️ Minimally Meets",1,IF(H31="❌ Does Not Meet",0,"—"))) -> 1 | J31: Staffing is listed by role per workstream, a start, but not framed as a quantified commitment (no FTE% or hours pledged).
D32: PRICING & STRATEGIC ALIGNMENT | E32: No consideration of pricing strategy in relation to commitment. | F32: Some consideration given to pricing strategy in relation to commitment. | G32: Executive and resource commitments are fully factored into pricing strategy. | H32: ❌ Does Not Meet | I32: =IF(H32="✅ Best Practice",2,IF(H32="⚠️ Minimally Meets",1,IF(H32="❌ Does Not Meet",0,"—"))) -> 0 | J32: Cannot assess — the Commercials table (slide 87) is entirely placeholder text ('xxx'), so pricing strategy can't be tied to any commitment.
D33: OUTCOME-BASED OPPORTUNITIES | E33: No mention of outcome-based models or value estimation. | F33: Some outcome-based opportunities included, but not clearly defined. | G33: Estimated outcomes and shared success models are presented with supporting rationale. | H33: ❌ Does Not Meet | I33: =IF(H33="✅ Best Practice",2,IF(H33="⚠️ Minimally Meets",1,IF(H33="❌ Does Not Meet",0,"—"))) -> 0 | J33: Only a straight Time & Material model is mentioned; no outcome-based or shared-success option presented.
D34: STRATEGIC DEAL ALIGNMENT | E34: Commitment feels generic and not scaled to the deal’s importance. | F34: Some alignment, but lacks depth in demonstrating mutual value. | G34: Commitment is scaled appropriately, ensuring a win-win for both Bristlecone and the client. | H34: ❌ Does Not Meet | I34: =IF(H34="✅ Best Practice",2,IF(H34="⚠️ Minimally Meets",1,IF(H34="❌ Does Not Meet",0,"—"))) -> 0 | J34: No language scaling Bristlecone's commitment to the size/importance of this specific four-workstream program.
B35: REFERENCES & TESTIMONIALS | C35: The proposal includes high-quality, relevant references that go beyond a basic logo slide, ensuring: − Deeply relevant case studies showcasing similar or applicable work. − Executive testimonials or quotes that reinforce key differentiators and value generated (not just generic praise like "worked hard" or "delivered on time and on budget"). − Clear business value articulation, with quantified benefits demonstrating impact. − Alignment with partnerships, where applicable, to showcase successful collaboration. | D35: CASE STUDY DEPTH & RELEVANCE | E35: Only includes a generic industry/technology logo slide. | F35: Case studies included but lack strong alignment or customization to the deal. | G35: Case studies are highly relevant, directly aligned with the deal scope. | H35: ✅ Best Practice | I35: =IF(H35="✅ Best Practice",2,IF(H35="⚠️ Minimally Meets",1,IF(H35="❌ Does Not Meet",0,"—"))) -> 2 | J35: Slides 91-92 show real, named client logos across relevant industries, including a directly on-point Semiconductor reference (global template, pilot deployment, rollouts, version upgrades).
D36: REFERENCE VALUE PROOF | E36: No quantified outcome in any cited reference or case study. | F36: References cite business impact but without specific metrics or client attribution. | G36: Each cited reference includes a quantified, client-attributed business outcome (e.g., '22% reduction in inventory' at [Client]). | H36: ⚠️ Minimally Meets | I36: =IF(H36="✅ Best Practice",2,IF(H36="⚠️ Minimally Meets",1,IF(H36="❌ Does Not Meet",0,"—"))) -> 1 | J36: Logos and process-scope tags are shown per reference, but no quantified, client-attributed outcome accompanies any specific one.
D37: TESTIMONIALS & EXECUTIVE QUOTES | E37: No quotes or only generic statements that don’t reinforce differentiators. | F37: Quotes included but not directly tied to key differentiators. | G37: Strong, strategic quotes that reinforce Bristlecone’s unique value in this engagement. | H37: ❌ Does Not Meet | I37: =IF(H37="✅ Best Practice",2,IF(H37="⚠️ Minimally Meets",1,IF(H37="❌ Does Not Meet",0,"—"))) -> 0 | J37: No client quotes or executive testimonials anywhere in the deck.
D38: PARTNERSHIP VALIDATION (IF APPLICABLE) | E38: No mention of joint success with a relevant partner. | F38: Some references to partnerships, but lacks clear proof of success. | G38: Demonstrates strong collaboration and partnership success where applicable. | H38: ❌ Does Not Meet | I38: =IF(H38="✅ Best Practice",2,IF(H38="⚠️ Minimally Meets",1,IF(H38="❌ Does Not Meet",0,"—"))) -> 0 | J38: No partner-specific success story shown (consistent with the Partnerships category gap).
B39: SOLUTION | C39: The proposed solution is comprehensive, tailored to the client, and integrates People, Process, and Technology holistically. It clearly defines scope: geographies, organizations, functional modules, customizations, number of users, and deployment approach. People: Organizational Change Management (OCM), governance framework, training for program team and end users. Technology: Functional and technical scope — custom developments, integrations, testing, cutover, data migrations, and deployment strategy (Waterfall, Agile, or Global Template). Process: Process assessments, KPIs, benchmarking, documentation, re-engineering, and operating model recommendations. AI Differentatiors, Assets, Agents to enhance delivery, automation, insights, and decision-making Business Value: A clear connection between how the solution is executed and the measurable outcomes it delivers. | D39: SOLUTION COMPLETENESS | E39: Major components (People, Process, or Technology) are missing or weakly defined. | F39: Covers all three areas but with minimal tailoring; could be reused for any client. | G39: Fully developed across People, Process, and Technology with clear AI integration and client-specific tailoring. | H39: ✅ Best Practice | I39: =IF(H39="✅ Best Practice",2,IF(H39="⚠️ Minimally Meets",1,IF(H39="❌ Does Not Meet",0,"—"))) -> 2 | J39: People, Process, and Technology are all addressed in real depth and tailored to Semtech's landscape (77 company codes, 190 plants, specific modules).
D40: CRITICAL SUCCESS FACTORS | E40: No mention of key success drivers for implementation. | F40: Some general success factors included, but not linked to the client’s situation. | G40: Success factors are well-defined and contextualized to the client’s specific transformation journey. | H40: ⚠️ Minimally Meets | I40: =IF(H40="✅ Best Practice",2,IF(H40="⚠️ Minimally Meets",1,IF(H40="❌ Does Not Meet",0,"—"))) -> 1 | J40: Downtime-reduction levers and quality gates are described, but not explicitly framed as 'critical success factors' tied to Semtech's transformation journey.
...

Sheet Summary and Scoring
B1: PROPOSAL REVIEW — SCORECARD SUMMARY
B3: Category | C3: Weight % | D3: Avg Score (0-2) | E3: Score % | F3: Weighted Score % | G3: Notes
B4: STRUCTURE | C4: 0.07 | D4: =AVERAGE('Pitch Checklist'!I4:I7) -> 1.5 | E4: =D4/2 -> 0.75 | F4: =E4*C4 -> 0.0525
B5: CUSTOMER CENTRICITY | C5: 0.1 | D5: =AVERAGE('Pitch Checklist'!I8:I10) -> 1.6666667 | E5: =D5/2 -> 0.83333333 | F5: =E5*C5 -> 0.083333333
B6: THOUGHT LEADERSHIP & EXPERTISE | C6: 0.07 | D6: =AVERAGE('Pitch Checklist'!I11:I14) -> 1.5 | E6: =D6/2 -> 0.75 | F6: =E6*C6 -> 0.0525
B7: PARTNERSHIPS | C7: 0.1 | D7: =AVERAGE('Pitch Checklist'!I15:I18) -> 0 | E7: =D7/2 -> 0 | F7: =E7*C7 -> 0
B8: TEAM | C8: 0.06 | D8: =AVERAGE('Pitch Checklist'!I19:I23) -> 0.4 | E8: =D8/2 -> 0.2 | F8: =E8*C8 -> 0.012
B9: BRANDING | C9: 0.05 | D9: =AVERAGE('Pitch Checklist'!I24:I29) -> 1.5 | E9: =D9/2 -> 0.75 | F9: =E9*C9 -> 0.0375
B10: EXECUTIVE COMMITMENT | C10: 0.05 | D10: =AVERAGE('Pitch Checklist'!I30:I34) -> 0.4 | E10: =D10/2 -> 0.2 | F10: =E10*C10 -> 0.01
B11: REFERENCES & TESTIMONIALS | C11: 0.05 | D11: =AVERAGE('Pitch Checklist'!I35:I38) -> 0.75 | E11: =D11/2 -> 0.375 | F11: =E11*C11 -> 0.01875
B12: SOLUTION | C12: 0.12 | D12: =AVERAGE('Pitch Checklist'!I39:I42) -> 1.5 | E12: =D12/2 -> 0.75 | F12: =E12*C12 -> 0.09
B13: METHODOLOGY, TOOLS & ACCELERATORS | C13: 0.08 | D13: =AVERAGE('Pitch Checklist'!I43:I46) -> 2 | E13: =D13/2 -> 1 | F13: =E13*C13 -> 0.08
B14: AI & INNOVATION | C14: 0.07 | D14: =AVERAGE('Pitch Checklist'!I47:I50) -> 2 | E14: =D14/2 -> 1 | F14: =E14*C14 -> 0.07
B15: COMMERCIALS, PRICING & INVESTMENT | C15: 0.08 | D15: =AVERAGE('Pitch Checklist'!I51:I54) -> 1 | E15: =D15/2 -> 0.5 | F15: =E15*C15 -> 0.04
B16: COMPETITIVE DIFFERENTIATION / WIN THEMES | C16: 0.07 | D16: =AVERAGE('Pitch Checklist'!I55:I57) -> 0.33333333 | E16: =D16/2 -> 0.16666667 | F16: =E16*C16 -> 0.011666667
B17: RISKS, ASSUMPTIONS & MITIGATION | C17: 0.03 | D17: =AVERAGE('Pitch Checklist'!I58:I60) -> 0.66666667 | E17: =D17/2 -> 0.33333333 | F17: =E17*C17 -> 0.01
B18: TOTAL | C18: =SUM(C4:C17) -> 1 | F18: =SUM(F4:F17) -> 0.56825 | G18: Overall weighted readiness score
B20: =IF(F18>=0.8,"✅ SUBMISSION-READY (≥80%)",IF(F18>=0.6,"⚠️ NEEDS WORK (60-79%) — address High/Critical gaps",IF(F18>0,"❌ NOT READY (<60%) — major rework required","— awaiting ratings —"))) -> ❌ NOT READY (<60%) — major rework required
B22: Notes: (1) If a whole category is Not Applicable for a deal (e.g., PARTNERSHIPS or REFERENCE on an informal pitch), set its Weight % to 0 and redistribute across the others so weights still total 100%. (2) Reviewed proposal: Technical Proposal for Semtech Migration - July 2026 (102 slides). No RFP/requirements doc was supplied, so this is rubric scoring only, no requirements-coverage cross-check. Reviewed by Claude at Priya's request, 2026-09-09.
